Workbook

Sheet Take Off
A1: MATERIALS | H1: LABOUR
A2: FOUNDATION
A3: One Bick wall | B3: Half Brick Wall | C3: Total Perimeter | D3: Total Area | E3: VERANDER | F3: Topsoil Excav | G3: PROJECT DISTANCE | H3: FOUNDATION
A4: 71.4 | B4: 55.45 | C4: =B4+A4 -> 126.85 | D4: 172 | E4: 4.5 | F4: =D4*0.4 -> 68.8 | G4: 200 | J4: =0.64+1.5+0.46 -> 2.6
A5: 167 | H5: Site Clearance | I5: Setting Out | J5: Excavation | K5: Footing Concrete | L5: Footing Brick work | M5: B/Filling& Raming | N5: Concrete Slab
A6: Excavation | B6: River Sand | C6: Pit Sand | D6: Concrete | E6: 230mm Brickforce | F6: 115mm Brickforce | G6: Gravel | H6: =+D4+A4 -> 243.4 | I6: =C4 -> 126.85 | J6: =C4 -> 126.85 | K6: =C4*0.7*0.23 -> 20.42285 | L6: =A15/48 -> 269.36141 | M6: =G7 -> 63.425 | N6: =D4*0.1 -> 17.2
A7: =C4*0.7*0.6 -> 53.277 | B7: =D12+F12 -> 112.86855 | C7: =E12*3 -> 155.15217 | D7: =D12+F12 -> 112.86855 | E7: =A4/15*3 -> 14.28 | F7: =B4/15*3 -> 11.09 | G7: =C4*0.5 -> 63.425
B8: =B7*2/11 -> 20.521555 | C8: =C7/8 -> 19.394022 | D8: =D7*2/11 -> 20.521555
H9: SUPER STRUCTURE
A10: BRICKS | B10: =1/0.085 -> 11.764706 | D10: CEMENT | G10: Termite Poisan
A11: 230 wall | B11: 115 wall | D11: Footing | E11: Brick work | F11: Slab | H11: B/Work to Ring Beam | I11: Above Ring Beam | J11: Ring Concrete | K11: Shuttering | L11: Steel fixing | M11: W/Frame Fitting | N11: D/Frame fitting
A12: =A4/0.23*2*15 -> 9313.0435 | B12: =B4/0.23*15 -> 3616.3043 | D12: =C4*0.23*0.7*3 -> 61.26855 | E12: =A15/250 -> 51.717391 | F12: =D4*0.1*3 -> 51.6 | G12: =D4/10 -> 17.2 | H12: =A25/48 -> 430.97826 | I12: =A36/48 -> 138.63678 | J12: =G22*3/11 -> 4.1204291 | K12: =C4 -> 126.85 | L12: =(D45+E45+F54)*6 -> 730.86 | M12: 13 | N12: =C54+D54 -> 9
A14: TOTAL BRICKS | B14: BRICKS T/TRIPS | C14: CEMENT T/TRIPS | D14: TOTAL TRIPS | G14: TOTAL CEMENT | H14: Beam Filling
A15: =A12+B12 -> 12929.348 | B15: =A15/3000 -> 4.3097826 | C15: =G15/100 -> 1.6458594 | G15: =D12+E12+F12 -> 164.58594 | H15: =A4*0.345 -> 24.633
B16: =G4*B15 -> 861.95652 | C16: =C15*G4 -> 329.17188 | D16: =B16+C16 -> 1191.1284
A18: SUPERSTRURE | B18: SUPER STRUCTURE
H19: PLASTERING
A20: BRICKS to Ringbeam | B20: =2.1/0.085 -> 24.705882 | D20: CEMENT
A21: 230 wall | B21: 115 wall | D21: Brick work | E21: Inter Plastering | F21: Ext Plastering | G21: Ring Beam | H21: Inter Plastering | I21: Ext Plastering | J21: Floors
A22: =A4/0.23*2*24 -> 14900.87 | B22: =B4/0.23*24 -> 5786.087 | D22: =A25/250 -> 82.747826 | E22: =F25/7 -> 56.614907 | F22: =E25/8 -> 19.402174 | G22: =A4*0.23*0.23*4 -> 15.10824 | H22: =F25+F36 -> 518.36051 | I22: =E25+E36 -> 206.95652 | J22: =D4 -> 172
A24: TOTAL | D24: Floors | E24: Ext Walls Area m2 | F24: Inter Walls Area m2
A25: =A22+B22 -> 20686.957 | D25: =D4*0.05*8 -> 68.8 | E25: =A22/48/2 -> 155.21739 | F25: =B22/48*2+E25 -> 396.30435
A27: BRICKS T/TRIPS | B27: CEMENT T/TRIPS | C27: TOTAL TRIPS | G27: TOTAL CEMENT
A28: =A25/3000 -> 6.8956522 | B28: =G28/100 -> 2.4267315 | C28: =A28+B28 -> 9.3223836 | G28: =D22+E22+F22+G22+D25 -> 242.67315
A29: =A28*G4 -> 1379.1304 | B29: =G4*B28 -> 485.34629 | C29: =A29+B29+C40 -> 2526.8466
A31: BRICKS Above Ringbeam | B31: =0.6/0.085 -> 7.0588235 | D31: CEMENT
A32: 230 wall | B32: 115 wall | D32: Brick work | E32: Inter Plastering | F32: Ext Plastering
A33: =A4/0.23*2*8 -> 4966.9565 | B33: =B4/0.23*7 -> 1687.6087 | D33: =A36/250 -> 26.618261 | E33: =F36/8 -> 15.25702 | F33: =E36/6 -> 8.6231884
A35: TOTAL | B35: CEMENT TOTAL | E35: Ext Walls Area m2 | F35: Inter Walls Area m2
A36: =A33+B33 -> 6654.5652 | B36: =D22+D33 -> 109.36609 | E36: =A33/48/2 -> 51.73913 | F36: =B33/48*2+E36 -> 122.05616
A38: BRICKS T/TRIPS | B38: CEMENT T/TRIPS | C38: TOTAL TRIPS
A39: =A36/3000 -> 2.2181884 | B39: =B36/100 -> 1.0936609 | C39: =A39*B39 -> 2.4259459
A40: =G4*A39 -> 443.63768 | B40: =G4*B39 -> 218.73217 | C40: =A40+B40 -> 662.36986
A42: AGGREGATES
A43: BRICK WORK
A44: River Sand | B44: Pit Sand | C44: Concrete | D44: 12mm D/Bars | E44: 10mm D/Bars | F44: 230mm Brick Force | G44: 11mm Brick Force
A45: =G22*2/11 -> 2.7469527 | B45: =B36*3/11 -> 29.827115 | C45: =G22*2/11 -> 2.7469527 | D45: =A4/5*4 -> 57.12 | E45: =(A4/0.2)*0.85/5 -> 60.69 | F45: =A4/15*8 -> 38.08 | G45: =B4/15*8 -> 29.573333
D47: 16mm D/Bars
D48: =E4/5*4 -> 3.6
A49: PLASTERING
...

Sheet MR AND MRS Matavakwa
B10: TIN NO: 2000873176
B11: VENDOR NO: 718689
E12: QUOTATION
B14: CUSTOMER INFO | E14: QUOTE # | G14: DATE
B15: Name: MR | E15: BM00215 | G15: 45204
B16: Address: | E16: CUSTOMER ID | G16: VALID UNTIL
B17: Phone, E-mail: | E17: AMS01 | G17: =G15+30 -> 45234
B18: Ref: PROPOSED MAIN HOUSE CONSTRUCTION
B20: WET TRADE MATERIALS AND SUNDRIES
B21: SUBSTRUCTURE ( FOUNDATION )
B22: Item | C22: Description | D22: Unit | E22: Qty | F22: Rate | G22: Amount
C24: Please Note
C25: Aggregates and cement include requirements for concrete bedding to drainage
B27: 1 | C27: Common bricks | D27: no | E27: ='Take Off'!A15 -> 12929.348 | F27: 0.16 | G27: =F27*E27 -> 2068.6957
B29: 2 | C29: River sand | D29: m3 | E29: ='Take Off'!B8+8 -> 28.521555 | F29: 20 | G29: =F29*E29 -> 570.43109
B31: 3 | C31: Pit sand | D31: m3 | E31: ='Take Off'!C8+1 -> 20.394022 | F31: 20 | G31: =F31*E31 -> 407.88043
B33: 4 | C33: 19mm Grenite Quarry Stone aggregate | D33: m3 | E33: ='Take Off'!D8+8 -> 28.521555 | F33: 45 | G33: =F33*E33 -> 1283.47
B35: 5 | C35: Imported inert granular fill/Hrdcore | D35: m3 | E35: ='Take Off'!G7 -> 63.425 | F35: 10 | G35: =F35*E35 -> 634.25
B37: 6 | C37: Cement PC 15 (50kg bags) | D37: bags | E37: ='Take Off'!F15 -> 0 | F37: 12.5 | G37: =F37*E37 -> 0
B39: 7 | C39: Termite Poison | D39: litre | E39: =+'Take Off'!G12*5 -> 86 | F39: 0.9 | G39: =F39*E39 -> 77.4
B41: 8 | C41: 250 Micron black polythene sheeting | D41: m² | E41: ='Take Off'!D4 -> 172 | F41: 1 | G41: =F41*E41 -> 172
B43: 9 | C43: Brickforce for one brick wall (20 metre rolls) Ref C2 | D43: rolls | E43: ='Take Off'!E7 -> 14.28 | F43: 2.5 | G43: =F43*E43 -> 35.7
B45: 10 | C45: Brickforce for half brick wall (20 metre rolls) Ref C2 | D45: rolls | E45: ='Take Off'!F7 -> 11.09 | F45: 2.5 | G45: =F45*E45 -> 27.725
B47: 11 | C47: Transport | D47: Km | E47: ='Take Off'!D16 -> 1191.1284 | F47: 0.65 | G47: =E47*F47 -> 774.23346
B49: Total Carried to Summary | G49: =SUM(G27:G48) -> 6051.7856
B51: SUPERSTRUCTURE (BRICKWORK, CONCRETE)
B52: Item | C52: Description | D52: Unit | E52: Qty | F52: Rate | G52: Amount
C53: In situ concrete and brickwork
B54: 1 | C54: Pit sand | D54: m3 | E54: ='Take Off'!B45 -> 29.827115 | F54: =F31 -> 20 | G54: =F54*E54 -> 596.54229
B56: 2 | C56: River Sand | D56: m³ | E56: ='Take Off'!A45+1 -> 3.7469527 | F56: =F29 -> 20 | G56: =F56*E56 -> 74.939055
B58: 3 | C58: Cement PC 15 (50kg bags) | D58: bags | E58: ='Take Off'!D22+'Take Off'!D33+'Take Off'!G22 -> 124.47433 | F58: =+F37 -> 12.5 | G58: =F58*E58 -> 1555.9291
B60: 4 | C60: 19mm Grenite Quarry Stone aggrecates | D60: m³ | E60: 2 | F60: =+F33 -> 45 | G60: =F60*E60 -> 90
B62: 5 | C62: Common bricks | D62: no | E62: ='Take Off'!A36+'Take Off'!A25 -> 27341.522 | F62: =F27 -> 0.16 | G62: =F62*E62 -> 4374.6435
B64: 6 | C64: Damp proof course for one brick wall (22 metre rolls) (230mm) | D64: rolls | E64: ='Take Off'!B54 -> 4.76 | F64: 3 | G64: =F64*E64 -> 14.28
B66: 7 | C66: Damp proof course for half brick wall (22 metre rolls) (115mm) | D66: rolls | E66: ='Take Off'!A54 -> 3.6966667 | F66: 2 | G66: =F66*E66 -> 7.3933333
B68: 8 | C68: Brickforce for one brick wall (20 metre rolls) (230mm) | D68: rolls | E68: ='Take Off'!F45 -> 38.08 | F68: 2.5 | G68: =F68*E68 -> 95.2
B70: 9 | C70: Brickforce for half brick wall (20 metre rolls)(115mm) | D70: rolls | E70: ='Take Off'!G45 -> 29.573333 | F70: 2.5 | G70: =F70*E70 -> 73.933333
B72: 10 | C72: Y16 reinforcemet steel | D72: Leng | E72: ='Take Off'!D48 -> 3.6 | F72: 8.8 | G72: =E72*F72 -> 31.68
B74: 11 | C74: Y12 reinforcemet steel | D74: length | E74: ='Take Off'!D45+'Take Off'!F54 -> 61.12 | F74: =4*1.3 -> 5.2 | G74: =F74*E74 -> 317.824
B76: 12 | C76: Y10 reinforcement steel | D76: length | E76: ='Take Off'!E45 -> 60.69 | F76: 3.9 | G76: =F76*E76 -> 236.691
...
